Workbook

Sheet Tienda_1
A1: Producto | B1: Categoría del Producto | C1: Precio | D1: Costo de envío | E1: Fecha de Compra | F1: Vendedor | G1: Lugar de Compra | H1: Calificación | I1: Método de pago | J1: Cantidad de cuotas | K1: lat | L1: lon
A2: Asistente virtual | B2: Electrónicos | C2: 164300 | D2: 6900 | E2: 16/01/2021 | F2: Pedro Gomez | G2: Bogotá | H2: 4 | I2: Tarjeta de crédito | J2: 8 | K2: 4.60971 | L2: -74.08175
A3: Mesa de comedor | B3: Muebles | C3: 192300 | D3: 8400 | E3: 18/05/2022 | F3: Beatriz Morales | G3: Medellín | H3: 1 | I3: Tarjeta de crédito | J3: 4 | K3: 6.25184 | L3: -75.56359
A4: Juego de mesa | B4: Juguetes | C4: 209600 | D4: 15900 | E4: 15/03/2021 | F4: Juan Fernandez | G4: Cartagena | H4: 1 | I4: Tarjeta de crédito | J4: 1 | K4: 10.39972 | L4: -75.51444
A5: Microondas | B5: Electrodomésticos | C5: 757500 | D5: 41000 | E5: 03/05/2022 | F5: Juan Fernandez | G5: Cali | H5: 4 | I5: Nequi | J5: 1 | K5: 3.43722 | L5: -76.5225
A6: Silla de oficina | B6: Muebles | C6: 335200 | D6: 20200 | E6: 07/11/2020 | F6: Maria Alfonso | G6: Medellín | H6: 5 | I6: Nequi | J6: 1 | K6: 6.25184 | L6: -75.56359
A7: Bloques de construcción | B7: Juguetes | C7: 24200 | D7: 0 | E7: 03/12/2020 | F7: Beatriz Morales | G7: Cali | H7: 5 | I7: Cupón | J7: 1 | K7: 3.43722 | L7: -76.5225
A8: Muñeca bebé | B8: Juguetes | C8: 44200 | D8: 0 | E8: 07/08/2021 | F8: Juan Fernandez | G8: Bogotá | H8: 3 | I8: Nequi | J8: 1 | K8: 4.60971 | L8: -74.08175
A9: Lavavajillas | B9: Electrodomésticos | C9: 1189700 | D9: 63700 | E9: 18/06/2021 | F9: Felipe Santos | G9: Santa Marta | H9: 5 | I9: Tarjeta de crédito | J9: 10 | K9: 11.24079 | L9: -74.19904
A10: Lavadora de ropa | B10: Electrodomésticos | C10: 1518200 | D10: 79000 | E10: 08/01/2022 | F10: Izabela de León | G10: Bogotá | H10: 1 | I10: Tarjeta de crédito | J10: 5 | K10: 4.60971 | L10: -74.08175
A11: Carrito de control remoto | B11: Juguetes | C11: 75200 | D11: 5100 | E11: 24/02/2020 | F11: Beatriz Morales | G11: Bogotá | H11: 5 | I11: Nequi | J11: 1 | K11: 4.60971 | L11: -74.08175
A12: Refrigerador | B12: Electrodomésticos | C12: 2431300 | D12: 127600 | E12: 03/04/2020 | F12: Blanca Ramirez | G12: Bogotá | H12: 5 | I12: Tarjeta de crédito | J12: 2 | K12: 4.60971 | L12: -74.08175
A13: Lavavajillas | B13: Electrodomésticos | C13: 1417100 | D13: 75700 | E13: 05/07/2021 | F13: Rafael Acosta | G13: Cartagena | H13: 5 | I13: Tarjeta de crédito | J13: 1 | K13: 10.39972 | L13: -75.51444
... A2360: Smartwatch | B2360: Electrónicos | C2360: 195000 | D2360: 8600 | E2360: 18/06/2022 | F2360: Felipe Santos | G2360: Cali | H2360: 4 | I2360: Tarjeta de crédito | J2360: 1 | K2360: 3.43722 | L2360: -76.5225

Sheet Tienda_2
A1: Producto | B1: Categoría del Producto | C1: Precio | D1: Costo de envío | E1: Fecha de Compra | F1: Vendedor | G1: Lugar de Compra | H1: Calificación | I1: Método de pago | J1: Cantidad de cuotas | K1: lat | L1: lon
A2: Silla de oficina | B2: Muebles | C2: 283600 | D2: 15300 | E2: 04/08/2021 | F2: Izabela de León | G2: Medellín | H2: 1 | I2: Nequi | J2: 1 | K2: 6.25184 | L2: -75.56359
A3: Pandereta | B3: Instrumentos musicales | C3: 76800 | D3: 2300 | E3: 26/11/2020 | F3: Blanca Ramirez | G3: Medellín | H3: 3 | I3: Tarjeta de crédito | J3: 4 | K3: 6.25184 | L3: -75.56359
A4: Cama king | B4: Muebles | C4: 443300 | D4: 23800 | E4: 22/10/2021 | F4: Izabela de León | G4: Pereira | H4: 5 | I4: Tarjeta de crédito | J4: 10 | K4: 4.81333 | L4: -75.69611
A5: Cama king | B5: Muebles | C5: 906200 | D5: 46400 | E5: 04/05/2022 | F5: Maria Alfonso | G5: Cali | H5: 5 | I5: Tarjeta de crédito | J5: 10 | K5: 3.43722 | L5: -76.5225
A6: Silla de oficina | B6: Muebles | C6: 397800 | D6: 19400 | E6: 26/02/2022 | F6: Lucas Olivera | G6: Bogotá | H6: 4 | I6: Tarjeta de crédito | J6: 3 | K6: 4.60971 | L6: -74.08175
A7: Guitarra acústica | B7: Instrumentos musicales | C7: 298400 | D7: 16100 | E7: 10/09/2021 | F7: Beatriz Morales | G7: Leticia | H7: 5 | I7: Tarjeta de crédito | J7: 3 | K7: -4.21528 | L7: -69.94056
A8: Mochila | B8: Deportes y diversión | C8: 105900 | D8: 9000 | E8: 10/06/2020 | F8: Blanca Ramirez | G8: Bogotá | H8: 1 | I8: Cupón | J8: 1 | K8: 4.60971 | L8: -74.08175
A9: Tablet ABXY | B9: Electrónicos | C9: 962600 | D9: 49400 | E9: 12/04/2022 | F9: Juliana Costa | G9: Medellín | H9: 4 | I9: Nequi | J9: 1 | K9: 6.25184 | L9: -75.56359
A10: Olla de presión | B10: Artículos para el hogar | C10: 82800 | D10: 4800 | E10: 11/04/2022 | F10: Izabela de León | G10: Barranquilla | H10: 5 | I10: Nequi | J10: 1 | K10: 10.96854 | L10: -74.78132
A11: Cubo mágico 8x8 | B11: Juguetes | C11: 9100 | D11: 3800 | E11: 04/09/2021 | F11: Camila Rivera | G11: Bogotá | H11: 5 | I11: Tarjeta de crédito | J11: 1 | K11: 4.60971 | L11: -74.08175
A12: Mochila | B12: Deportes y diversión | C12: 86800 | D12: 9300 | E12: 18/04/2020 | F12: Izabela de León | G12: Medellín | H12: 5 | I12: Tarjeta de crédito | J12: 5 | K12: 6.25184 | L12: -75.56359
A13: Secadora de ropa | B13: Electrodomésticos | C13: 878900 | D13: 47000 | E13: 25/09/2021 | F13: Rafael Acosta | G13: Barranquilla | H13: 1 | I13: Tarjeta de crédito | J13: 2 | K13: 10.96854 | L13: -74.78132
... A2360: Bicicleta | B2360: Deportes y diversión | C2360: 551000 | D2360: 27500 | E2360: 03/09/2022 | F2360: Maria Alfonso | G2360: Medellín | H2360: 4 | I2360: Tarjeta de crédito | J2360: 1 | K2360: 6.25184 | L2360: -75.56359

Sheet Tienda_3
A1: Producto | B1: Categoría del Producto | C1: Precio | D1: Costo de envío | E1: Fecha de Compra | F1: Vendedor | G1: Lugar de Compra | H1: Calificación | I1: Método de pago | J1: Cantidad de cuotas | K1: lat | L1: lon
A2: Secadora de ropa | B2: Electrodomésticos | C2: 1285100 | D2: 66600 | E2: 17/12/2021 | F2: Camila Rivera | G2: Santa Marta | H2: 4 | I2: Tarjeta de crédito | J2: 4 | K2: 11.24079 | L2: -74.19904
A3: Mesa de noche | B3: Muebles | C3: 290100 | D3: 13600 | E3: 10/02/2021 | F3: Maria Alfonso | G3: Cali | H3: 3 | I3: Tarjeta de crédito | J3: 1 | K3: 3.43722 | L3: -76.5225
A4: Guitarra acústica | B4: Instrumentos musicales | C4: 303500 | D4: 17400 | E4: 22/01/2023 | F4: Lucas Olivera | G4: Bogotá | H4: 5 | I4: Tarjeta de crédito | J4: 3 | K4: 4.60971 | L4: -74.08175
A5: Balón de voleibol | B5: Deportes y diversión | C5: 58800 | D5: 3300 | E5: 22/03/2022 | F5: Pedro Gomez | G5: Barranquilla | H5: 4 | I5: Tarjeta de crédito | J5: 6 | K5: 10.96854 | L5: -74.78132
A6: Armario | B6: Muebles | C6: 521100 | D6: 25900 | E6: 12/01/2022 | F6: Blanca Ramirez | G6: Bogotá | H6: 1 | I6: Tarjeta de crédito | J6: 1 | K6: 4.60971 | L6: -74.08175
A7: Impresora | B7: Electrónicos | C7: 230700 | D7: 10500 | E7: 20/11/2022 | F7: Mariana Herrera | G7: Medellín | H7: 5 | I7: Tarjeta de crédito | J7: 5 | K7: 6.25184 | L7: -75.56359
A8: Carrito de control remoto | B8: Juguetes | C8: 55700 | D8: 3200 | E8: 07/07/2020 | F8: Ángel Rodriguez | G8: Bogotá | H8: 2 | I8: Nequi | J8: 1 | K8: 4.60971 | L8: -74.08175
A9: Silla de oficina | B9: Muebles | C9: 464600 | D9: 25100 | E9: 01/05/2022 | F9: Santiago Silva | G9: Bogotá | H9: 5 | I9: Nequi | J9: 1 | K9: 4.60971 | L9: -74.08175
A10: Pandereta | B10: Instrumentos musicales | C10: 43500 | D10: 2700 | E10: 27/10/2021 | F10: Maria Alfonso | G10: Medellín | H10: 5 | I10: Tarjeta de crédito | J10: 3 | K10: 6.25184 | L10: -75.56359
A11: Cubertería | B11: Artículos para el hogar | C11: 33500 | D11: 0 | E11: 03/05/2022 | F11: Felipe Santos | G11: Medellín | H11: 5 | I11: Nequi | J11: 1 | K11: 6.25184 | L11: -75.56359
A12: Muñeca bebé | B12: Juguetes | C12: 45500 | D12: 0 | E12: 16/08/2021 | F12: Beatriz Morales | G12: Neiva | H12: 5 | I12: Nequi | J12: 1 | K12: 2.9273 | L12: -75.28189
A13: Silla de oficina | B13: Muebles | C13: 435200 | D13: 21400 | E13: 25/09/2022 | F13: Felipe Santos | G13: Cúcuta | H13: 2 | I13: Tarjeta de crédito | J13: 1 | K13: 7.89391 | L13: -72.50782
... A2360: Modelado predictivo | B2360: Libros | C2360: 63400 | D2360: 9400 | E2360: 24/05/2022 | F2360: Mariana Herrera | G2360: Medellín | H2360: 5 | I2360: Tarjeta de crédito | J2360: 10 | K2360: 6.25184 | L2360: -75.56359

Sheet Tienda_4
A1: Producto | B1: Categoría del Producto | C1: Precio | D1: Costo de envío | E1: Fecha de Compra | F1: Vendedor | G1: Lugar de Compra | H1: Calificación | I1: Método de pago | J1: Cantidad de cuotas | K1: lat | L1: lon
A2: Lavavajillas | B2: Electrodomésticos | C2: 1084800 | D2: 56000 | E2: 11/11/2022 | F2: Rafael Acosta | G2: Bogotá | H2: 4 | I2: Tarjeta de crédito | J2: 3 | K2: 4.60971 | L2: -74.08175
A3: Cama box | B3: Muebles | C3: 473800 | D3: 25400 | E3: 03/01/2020 | F3: Izabela de León | G3: Cúcuta | H3: 5 | I3: Tarjeta de crédito | J3: 2 | K3: 7.89391 | L3: -72.50782
A4: Balón de baloncesto | B4: Deportes y diversión | C4: 23700 | D4: 0 | E4: 25/12/2022 | F4: Maria Alfonso | G4: Medellín | H4: 5 | I4: Nequi | J4: 1 | K4: 6.25184 | L4: -75.56359
A5: Modelado predictivo | B5: Libros | C5: 57700 | D5: 1300 | E5: 23/11/2021 | F5: Lucas Olivera | G5: Medellín | H5: 3 | I5: Nequi | J5: 1 | K5: 6.25184 | L5: -75.56359
A6: Auriculares | B6: Electrónicos | C6: 138900 | D6: 5600 | E6: 25/04/2022 | F6: Blanca Ramirez | G6: Bogotá | H6: 4 | I6: Tarjeta de crédito | J6: 7 | K6: 4.60971 | L6: -74.08175
A7: Refrigerador | B7: Electrodomésticos | C7: 1591900 | D7: 83000 | E7: 30/05/2020 | F7: Beatriz Morales | G7: Cartagena | H7: 1 | I7: Tarjeta de crédito | J7: 10 | K7: 10.39972 | L7: -75.51444
A8: Guitarra eléctrica | B8: Instrumentos musicales | C8: 626200 | D8: 38000 | E8: 11/07/2021 | F8: Izabela de León | G8: Medellín | H8: 5 | I8: Tarjeta de crédito | J8: 1 | K8: 6.25184 | L8: -75.56359
A9: Auriculares con micrófono | B9: Electrónicos | C9: 94500 | D9: 11900 | E9: 19/02/2022 | F9: Santiago Silva | G9: Medellín | H9: 4 | I9: Tarjeta de crédito | J9: 2 | K9: 6.25184 | L9: -75.56359
A10: Iphone 15 | B10: Electrónicos | C10: 2339000 | D10: 122700 | E10: 15/10/2022 | F10: Camila Rivera | G10: Bogotá | H10: 5 | I10: Tarjeta de crédito | J10: 3 | K10: 4.60971 | L10: -74.08175
A11: Mesa de noche | B11: Muebles | C11: 273300 | D11: 21900 | E11: 18/11/2022 | F11: Rafael Acosta | G11: Bogotá | H11: 1 | I11: Tarjeta de crédito | J11: 3 | K11: 4.60971 | L11: -74.08175
A12: Balón de baloncesto | B12: Deportes y diversión | C12: 68000 | D12: 6000 | E12: 03/03/2022 | F12: Felipe Santos | G12: Manizales | H12: 4 | I12: Nequi | J12: 1 | K12: 5.06889 | L12: -75.51738
A13: Muñeca bebé | B13: Juguetes | C13: 47500 | D13: 0 | E13: 16/09/2020 | F13: Pedro Gomez | G13: Bogotá | H13: 5 | I13: Tarjeta de crédito | J13: 2 | K13: 4.60971 | L13: -74.08175
... A2359: Cuerda para saltar | B2359: Deportes y diversión | C2359: 11200 | D2359: 1300 | E2359: 17/11/2021 | F2359: Felipe Santos | G2359: Bogotá | H2359: 5 | I2359: Tarjeta de crédito | J2359: 1 | K2359: 4.60971 | L2359: -74.08175

Sheet Análisis
A1: Análisis de ventas — Tiendas 1 a 4
A2: Todas las cifras se recalculan automáticamente al editar los datos de las hojas Tienda_1 a Tienda_4. | J2: Datos de apoyo para gráficos (calculados)
A4: 1. Resumen por tienda | J4: Tienda | K4: Ingresos
A5: Métrica | B5: Tienda 1 | C5: Tienda 2 | D5: Tienda 3 | E5: Tienda 4 | F5: Total / Prom. | J5: =B5 -> Tienda 1 | K5: =B7 -> 1150880400
A6: N° de ventas | B6: =COUNTA(Tienda_1!$A$2:$A$100000) -> 2359 | C6: =COUNTA(Tienda_2!$A$2:$A$100000) -> 2359 | D6: =COUNTA(Tienda_3!$A$2:$A$100000) -> 2359 | E6: =COUNTA(Tienda_4!$A$2:$A$100000) -> 2358 | F6: =SUM(B6:E6) -> 9435 | J6: =C5 -> Tienda 2 | K6: =C7 -> 1116343500
A7: Ingresos totales ($) | B7: =SUM(Tienda_1!$C$2:$C$100000) -> 1150880400 | C7: =SUM(Tienda_2!$C$2:$C$100000) -> 1116343500 | D7: =SUM(Tienda_3!$C$2:$C$100000) -> 1098019600 | E7: =SUM(Tienda_4!$C$2:$C$100000) -> 1038375700 | F7: =SUM(B7:E7) -> 4403619200 | J7: =D5 -> Tienda 3 | K7: =D7 -> 1098019600
A8: Ticket promedio ($) | B8: =IFERROR(B7/B6,0) -> 487867.91 | C8: =IFERROR(C7/C6,0) -> 473227.43 | D8: =IFERROR(D7/D6,0) -> 465459.77 | E8: =IFERROR(E7/E6,0) -> 440362.89 | F8: =IFERROR(F7/F6,0) -> 466732.29 | J8: =E5 -> Tienda 4 | K8: =E7 -> 1038375700
A9: Costo de envío total ($) | B9: =SUM(Tienda_1!$D$2:$D$100000) -> 61377900 | C9: =SUM(Tienda_2!$D$2:$D$100000) -> 59485100 | D9: =SUM(Tienda_3!$D$2:$D$100000) -> 58516600 | E9: =SUM(Tienda_4!$D$2:$D$100000) -> 55317400 | F9: =SUM(B9:E9) -> 234697000
A10: Costo de envío promedio ($) | B10: =IFERROR(B9/B6,0) -> 26018.61 | C10: =IFERROR(C9/C6,0) -> 25216.236 | D10: =IFERROR(D9/D6,0) -> 24805.68 | E10: =IFERROR(E9/E6,0) -> 23459.457 | F10: =IFERROR(F9/F6,0) -> 24875.146 | J10: Categoría | K10: Ingresos
A11: Ingreso neto de envíos ($) | B11: =B7-B9 -> 1089502500 | C11: =C7-C9 -> 1056858400 | D11: =D7-D9 -> 1039503000 | E11: =E7-E9 -> 983058300 | F11: =F7-F9 -> 4168922200 | J11: =A18 -> Artículos para el hogar | K11: =F18 -> 57579800
A12: Calificación promedio | B12: =IFERROR(AVERAGE(Tienda_1!$H$2:$H$100000),0) -> 3.976685 | C12: =IFERROR(AVERAGE(Tienda_2!$H$2:$H$100000),0) -> 4.0373039 | D12: =IFERROR(AVERAGE(Tienda_3!$H$2:$H$100000),0) -> 4.0483256 | E12: =IFERROR(AVERAGE(Tienda_4!$H$2:$H$100000),0) -> 3.9957591 | F12: =IFERROR(SUMPRODUCT(B12:E12,B6:E6)/F6,0) -> 4.0145204 | J12: =A19 -> Deportes y diversión | K12: =F19 -> 142977700
A13: Cuotas promedio | B13: =IFERROR(AVERAGE(Tienda_1!$J$2:$J$100000),0) -> 2.9431963 | C13: =IFERROR(AVERAGE(Tienda_2!$J$2:$J$100000),0) -> 2.9025011 | D13: =IFERROR(AVERAGE(Tienda_3!$J$2:$J$100000),0) -> 2.967783 | E13: =IFERROR(AVERAGE(Tienda_4!$J$2:$J$100000),0) -> 2.8960984 | F13: =IFERROR(SUMPRODUCT(B13:E13,B6:E6)/F6,0) -> 2.927398 | J13: =A20 -> Electrodomésticos | K13: =F20 -> 1324751100
A14: Participación en ingresos | B14: =IFERROR(B7/$F$7,0) -> 0.26134876 | C14: =IFERROR(C7/$F$7,0) -> 0.25350591 | D14: =IFERROR(D7/$F$7,0) -> 0.24934481 | E14: =IFERROR(E7/$F$7,0) -> 0.23580052 | F14: =SUM(B14:E14) -> 1 | J14: =A21 -> Electrónicos | K14: =F21 -> 1660576500
J15: =A22 -> Instrumentos musicales | K15: =F22 -> 348772600
A16: 2. Ingresos por categoría de producto | J16: =A23 -> Juguetes | K16: =F23 -> 73604400
A17: Categoría | B17: Tienda 1 | C17: Tienda 2 | D17: Tienda 3 | E17: Tienda 4 | F17: Total ingresos | G17: % del total | H17: N° de ventas | J17: =A24 -> Libros | K17: =F24 -> 37696100
A18: Artículos para el hogar | B18: =SUMIF(Tienda_1!$B$2:$B$100000,$A18,Tienda_1!$C$2:$C$100000) -> 12698400 | C18: =SUMIF(Tienda_2!$B$2:$B$100000,$A18,Tienda_2!$C$2:$C$100000) -> 14746900 | D18: =SUMIF(Tienda_3!$B$2:$B$100000,$A18,Tienda_3!$C$2:$C$100000) -> 15060000 | E18: =SUMIF(Tienda_4!$B$2:$B$100000,$A18,Tienda_4!$C$2:$C$100000) -> 15074500 | F18: =SUM(B18:E18) -> 57579800 | G18: =IFERROR(F18/$F$26,0) -> 0.013075563 | H18: =COUNTIF(Tienda_1!$B$2:$B$100000,$A18)+COUNTIF(Tienda_2!$B$2:$B$100000,$A18)+COUNTIF(Tienda_3!$B$2:$B$100000,$A18)+COUNTIF(Tienda_4!$B$2:$B$100000,$A18) -> 730 | J18: =A25 -> Muebles | K18: =F25 -> 757661000
A19: Deportes y diversión | B19: =SUMIF(Tienda_1!$B$2:$B$100000,$A19,Tienda_1!$C$2:$C$100000) -> 39290000 | C19: =SUMIF(Tienda_2!$B$2:$B$100000,$A19,Tienda_2!$C$2:$C$100000) -> 34744500 | D19: =SUMIF(Tienda_3!$B$2:$B$100000,$A19,Tienda_3!$C$2:$C$100000) -> 35593100 | E19: =SUMIF(Tienda_4!$B$2:$B$100000,$A19,Tienda_4!$C$2:$C$100000) -> 33350100 | F19: =SUM(B19:E19) -> 142977700 | G19: =IFERROR(F19/$F$26,0) -> 0.032468225 | H19: =COUNTIF(Tienda_1!$B$2:$B$100000,$A19)+COUNTIF(Tienda_2!$B$2:$B$100000,$A19)+COUNTIF(Tienda_3!$B$2:$B$100000,$A19)+COUNTIF(Tienda_4!$B$2:$B$100000,$A19) -> 1113
A20: Electrodomésticos | B20: =SUMIF(Tienda_1!$B$2:$B$100000,$A20,Tienda_1!$C$2:$C$100000) -> 363685200 | C20: =SUMIF(Tienda_2!$B$2:$B$100000,$A20,Tienda_2!$C$2:$C$100000) -> 348567800 | D20: =SUMIF(Tienda_3!$B$2:$B$100000,$A20,Tienda_3!$C$2:$C$100000) -> 329237900 | E20: =SUMIF(Tienda_4!$B$2:$B$100000,$A20,Tienda_4!$C$2:$C$100000) -> 283260200 | F20: =SUM(B20:E20) -> 1324751100 | G20: =IFERROR(F20/$F$26,0) -> 0.30083235 | H20: =COUNTIF(Tienda_1!$B$2:$B$100000,$A20)+COUNTIF(Tienda_2!$B$2:$B$100000,$A20)+COUNTIF(Tienda_3!$B$2:$B$100000,$A20)+COUNTIF(Tienda_4!$B$2:$B$100000,$A20) -> 1149
A21: Electrónicos | B21: =SUMIF(Tienda_1!$B$2:$B$100000,$A21,Tienda_1!$C$2:$C$100000) -> 429493500 | C21: =SUMIF(Tienda_2!$B$2:$B$100000,$A21,Tienda_2!$C$2:$C$100000) -> 410831100 | D21: =SUMIF(Tienda_3!$B$2:$B$100000,$A21,Tienda_3!$C$2:$C$100000) -> 410775800 | E21: =SUMIF(Tienda_4!$B$2:$B$100000,$A21,Tienda_4!$C$2:$C$100000) -> 409476100 | F21: =SUM(B21:E21) -> 1660576500 | G21: =IFERROR(F21/$F$26,0) -> 0.37709357 | H21: =COUNTIF(Tienda_1!$B$2:$B$100000,$A21)+COUNTIF(Tienda_2!$B$2:$B$100000,$A21)+COUNTIF(Tienda_3!$B$2:$B$100000,$A21)+COUNTIF(Tienda_4!$B$2:$B$100000,$A21) -> 1772 | J21: Año | K21: Ingresos
A22: Instrumentos musicales | B22: =SUMIF(Tienda_1!$B$2:$B$100000,$A22,Tienda_1!$C$2:$C$100000) -> 91299000 | C22: =SUMIF(Tienda_2!$B$2:$B$100000,$A22,Tienda_2!$C$2:$C$100000) -> 104990300 | D22: =SUMIF(Tienda_3!$B$2:$B$100000,$A22,Tienda_3!$C$2:$C$100000) -> 77380900 | E22: =SUMIF(Tienda_4!$B$2:$B$100000,$A22,Tienda_4!$C$2:$C$100000) -> 75102400 | F22: =SUM(B22:E22) -> 348772600 | G22: =IFERROR(F22/$F$26,0) -> 0.079201353 | H22: =COUNTIF(Tienda_1!$B$2:$B$100000,$A22)+COUNTIF(Tienda_2!$B$2:$B$100000,$A22)+COUNTIF(Tienda_3!$B$2:$B$100000,$A22)+COUNTIF(Tienda_4!$B$2:$B$100000,$A22) -> 753 | J22: =TEXT(A71,"0") -> 2020 | K22: =F71 -> 1341955000
A23: Juguetes | B23: =SUMIF(Tienda_1!$B$2:$B$100000,$A23,Tienda_1!$C$2:$C$100000) -> 17995700 | C23: =SUMIF(Tienda_2!$B$2:$B$100000,$A23,Tienda_2!$C$2:$C$100000) -> 15945400 | D23: =SUMIF(Tienda_3!$B$2:$B$100000,$A23,Tienda_3!$C$2:$C$100000) -> 19401100 | E23: =SUMIF(Tienda_4!$B$2:$B$100000,$A23,Tienda_4!$C$2:$C$100000) -> 20262200 | F23: =SUM(B23:E23) -> 73604400 | G23: =IFERROR(F23/$F$26,0) -> 0.016714524 | H23: =COUNTIF(Tienda_1!$B$2:$B$100000,$A23)+COUNTIF(Tienda_2!$B$2:$B$100000,$A23)+COUNTIF(Tienda_3!$B$2:$B$100000,$A23)+COUNTIF(Tienda_4!$B$2:$B$100000,$A23) -> 1290 | J23: =TEXT(A72,"0") -> 2021 | K23: =F72 -> 1424114300
A24: Libros | B24: =SUMIF(Tienda_1!$B$2:$B$100000,$A24,Tienda_1!$C$2:$C$100000) -> 8784900 | C24: =SUMIF(Tienda_2!$B$2:$B$100000,$A24,Tienda_2!$C$2:$C$100000) -> 10091200 | D24: =SUMIF(Tienda_3!$B$2:$B$100000,$A24,Tienda_3!$C$2:$C$100000) -> 9498700 | E24: =SUMIF(Tienda_4!$B$2:$B$100000,$A24,Tienda_4!$C$2:$C$100000) -> 9321300 | F24: =SUM(B24:E24) -> 37696100 | G24: =IFERROR(F24/$F$26,0) -> 0.0085602543 | H24: =COUNTIF(Tienda_1!$B$2:$B$100000,$A24)+COUNTIF(Tienda_2!$B$2:$B$100000,$A24)+COUNTIF(Tienda_3!$B$2:$B$100000,$A24)+COUNTIF(Tienda_4!$B$2:$B$100000,$A24) -> 742 | J24: =TEXT(A73,"0") -> 2022 | K24: =F73 -> 1327451900
A25: Muebles | B25: =SUMIF(Tienda_1!$B$2:$B$100000,$A25,Tienda_1!$C$2:$C$100000) -> 187633700 | C25: =SUMIF(Tienda_2!$B$2:$B$100000,$A25,Tienda_2!$C$2:$C$100000) -> 176426300 | D25: =SUMIF(Tienda_3!$B$2:$B$100000,$A25,Tienda_3!$C$2:$C$100000) -> 201072100 | E25: =SUMIF(Tienda_4!$B$2:$B$100000,$A25,Tienda_4!$C$2:$C$100000) -> 192528900 | F25: =SUM(B25:E25) -> 757661000 | G25: =IFERROR(F25/$F$26,0) -> 0.17205416 | H25: =COUNTIF(Tienda_1!$B$2:$B$100000,$A25)+COUNTIF(Tienda_2!$B$2:$B$100000,$A25)+COUNTIF(Tienda_3!$B$2:$B$100000,$A25)+COUNTIF(Tienda_4!$B$2:$B$100000,$A25) -> 1886 | J25: =TEXT(A74,"0") -> 2023 | K25: =F74 -> 310098000
A26: Total | B26: =SUM(B18:B25) -> 1150880400 | C26: =SUM(C18:C25) -> 1116343500 | D26: =SUM(D18:D25) -> 1098019600 | E26: =SUM(E18:E25) -> 1038375700 | F26: =SUM(F18:F25) -> 4403619200 | G26: =SUM(G18:G25) -> 1 | H26: =SUM(H18:H25) -> 9435
A28: 3. Ingresos por ciudad de compra
A29: Ciudad | B29: Tienda 1 | C29: Tienda 2 | D29: Tienda 3 | E29: Tienda 4 | F29: Total ingresos | G29: % del total | H29: N° de ventas
A30: Armenia | B30: =SUMIF(Tienda_1!$G$2:$G$100000,$A30,Tienda_1!$C$2:$C$100000) -> 4615700 | C30: =SUMIF(Tienda_2!$G$2:$G$100000,$A30,Tienda_2!$C$2:$C$100000) -> 3363200 | D30: =SUMIF(Tienda_3!$G$2:$G$100000,$A30,Tienda_3!$C$2:$C$100000) -> 3980300 | E30: =SUMIF(Tienda_4!$G$2:$G$100000,$A30,Tienda_4!$C$2:$C$100000) -> 283700 | F30: =SUM(B30:E30) -> 12242900 | G30: =IFERROR(F30/$F$49,0) -> 0.0027801904 | H30: =COUNTIF(Tienda_1!$G$2:$G$100000,$A30)+COUNTIF(Tienda_2!$G$2:$G$100000,$A30)+COUNTIF(Tienda_3!$G$2:$G$100000,$A30)+COUNTIF(Tienda_4!$G$2:$G$100000,$A30) -> 28
A31: Barranquilla | B31: =SUMIF(Tienda_1!$G$2:$G$100000,$A31,Tienda_1!$C$2:$C$100000) -> 32907700 | C31: =SUMIF(Tienda_2!$G$2:$G$100000,$A31,Tienda_2!$C$2:$C$100000) -> 27741300 | D31: =SUMIF(Tienda_3!$G$2:$G$100000,$A31,Tienda_3!$C$2:$C$100000) -> 36768500 | E31: =SUMIF(Tienda_4!$G$2:$G$100000,$A31,Tienda_4!$C$2:$C$100000) -> 34623000 | F31: =SUM(B31:E31) -> 132040500 | G31: =IFERROR(F31/$F$49,0) -> 0.029984541 | H31: =COUNTIF(Tienda_1!$G$2:$G$100000,$A31)+COUNTIF(Tienda_2!$G$2:$G$100000,$A31)+COUNTIF(Tienda_3!$G$2:$G$100000,$A31)+COUNTIF(Tienda_4!$G$2:$G$100000,$A31) -> 310
A32: Bogotá | B32: =SUMIF(Tienda_1!$G$2:$G$100000,$A32,Tienda_1!$C$2:$C$100000) -> 440005000 | C32: =SUMIF(Tienda_2!$G$2:$G$100000,$A32,Tienda_2!$C$2:$C$100000) -> 479959200 | D32: =SUMIF(Tienda_3!$G$2:$G$100000,$A32,Tienda_3!$C$2:$C$100000) -> 475562100 | E32: =SUMIF(Tienda_4!$G$2:$G$100000,$A32,Tienda_4!$C$2:$C$100000) -> 419332000 | F32: =SUM(B32:E32) -> 1814858300 | G32: =IFERROR(F32/$F$49,0) -> 0.4121288 | H32: =COUNTIF(Tienda_1!$G$2:$G$100000,$A32)+COUNTIF(Tienda_2!$G$2:$G$100000,$A32)+COUNTIF(Tienda_3!$G$2:$G$100000,$A32)+COUNTIF(Tienda_4!$G$2:$G$100000,$A32) -> 3943
A33: Bucaramanga | B33: =SUMIF(Tienda_1!$G$2:$G$100000,$A33,Tienda_1!$C$2:$C$100000) -> 17579200 | C33: =SUMIF(Tienda_2!$G$2:$G$100000,$A33,Tienda_2!$C$2:$C$100000) -> 23895600 | D33: =SUMIF(Tienda_3!$G$2:$G$100000,$A33,Tienda_3!$C$2:$C$100000) -> 23538900 | E33: =SUMIF(Tienda_4!$G$2:$G$100000,$A33,Tienda_4!$C$2:$C$100000) -> 25559600 | F33: =SUM(B33:E33) -> 90573300 | G33: =IFERROR(F33/$F$49,0) -> 0.020567923 | H33: =COUNTIF(Tienda_1!$G$2:$G$100000,$A33)+COUNTIF(Tienda_2!$G$2:$G$100000,$A33)+COUNTIF(Tienda_3!$G$2:$G$100000,$A33)+COUNTIF(Tienda_4!$G$2:$G$100000,$A33) -> 181
A34: Cali | B34: =SUMIF(Tienda_1!$G$2:$G$100000,$A34,Tienda_1!$C$2:$C$100000) -> 154493700 | C34: =SUMIF(Tienda_2!$G$2:$G$100000,$A34,Tienda_2!$C$2:$C$100000) -> 118257600 | D34: =SUMIF(Tienda_3!$G$2:$G$100000,$A34,Tienda_3!$C$2:$C$100000) -> 109287600 | E34: =SUMIF(Tienda_4!$G$2:$G$100000,$A34,Tienda_4!$C$2:$C$100000) -> 124487200 | F34: =SUM(B34:E34) -> 506526100 | G34: =IFERROR(F34/$F$49,0) -> 0.11502495 | H34: =COUNTIF(Tienda_1!$G$2:$G$100000,$A34)+COUNTIF(Tienda_2!$G$2:$G$100000,$A34)+COUNTIF(Tienda_3!$G$2:$G$100000,$A34)+COUNTIF(Tienda_4!$G$2:$G$100000,$A34) -> 1007
A35: Cartagena | B35: =SUMIF(Tienda_1!$G$2:$G$100000,$A35,Tienda_1!$C$2:$C$100000) -> 22296700 | C35: =SUMIF(Tienda_2!$G$2:$G$100000,$A35,Tienda_2!$C$2:$C$100000) -> 21548300 | D35: =SUMIF(Tienda_3!$G$2:$G$100000,$A35,Tienda_3!$C$2:$C$100000) -> 34144100 | E35: =SUMIF(Tienda_4!$G$2:$G$100000,$A35,Tienda_4!$C$2:$C$100000) -> 24387600 | F35: =SUM(B35:E35) -> 102376700 | G35: =IFERROR(F35/$F$49,0) -> 0.023248309 | H35: =COUNTIF(Tienda_1!$G$2:$G$100000,$A35)+COUNTIF(Tienda_2!$G$2:$G$100000,$A35)+COUNTIF(Tienda_3!$G$2:$G$100000,$A35)+COUNTIF(Tienda_4!$G$2:$G$100000,$A35) -> 242
A36: Cúcuta | B36: =SUMIF(Tienda_1!$G$2:$G$100000,$A36,Tienda_1!$C$2:$C$100000) -> 37879500 | C36: =SUMIF(Tienda_2!$G$2:$G$100000,$A36,Tienda_2!$C$2:$C$100000) -> 28991500 | D36: =SUMIF(Tienda_3!$G$2:$G$100000,$A36,Tienda_3!$C$2:$C$100000) -> 25165500 | E36: =SUMIF(Tienda_4!$G$2:$G$100000,$A36,Tienda_4!$C$2:$C$100000) -> 7332600 | F36: =SUM(B36:E36) -> 99369100 | G36: =IFERROR(F36/$F$49,0) -> 0.022565325 | H36: =COUNTIF(Tienda_1!$G$2:$G$100000,$A36)+COUNTIF(Tienda_2!$G$2:$G$100000,$A36)+COUNTIF(Tienda_3!$G$2:$G$100000,$A36)+COUNTIF(Tienda_4!$G$2:$G$100000,$A36) -> 186
A37: Inírida | B37: =SUMIF(Tienda_1!$G$2:$G$100000,$A37,Tienda_1!$C$2:$C$100000) -> 2722500 | C37: =SUMIF(Tienda_2!$G$2:$G$100000,$A37,Tienda_2!$C$2:$C$100000) -> 2504600 | D37: =SUMIF(Tienda_3!$G$2:$G$100000,$A37,Tienda_3!$C$2:$C$100000) -> 1333700 | E37: =SUMIF(Tienda_4!$G$2:$G$100000,$A37,Tienda_4!$C$2:$C$100000) -> 1527100 | F37: =SUM(B37:E37) -> 8087900 | G37: =IFERROR(F37/$F$49,0) -> 0.0018366484 | H37: =COUNTIF(Tienda_1!$G$2:$G$100000,$A37)+COUNTIF(Tienda_2!$G$2:$G$100000,$A37)+COUNTIF(Tienda_3!$G$2:$G$100000,$A37)+COUNTIF(Tienda_4!$G$2:$G$100000,$A37) -> 14
A38: Leticia | B38: =SUMIF(Tienda_1!$G$2:$G$100000,$A38,Tienda_1!$C$2:$C$100000) -> 14669800 | C38: =SUMIF(Tienda_2!$G$2:$G$100000,$A38,Tienda_2!$C$2:$C$100000) -> 16159000 | D38: =SUMIF(Tienda_3!$G$2:$G$100000,$A38,Tienda_3!$C$2:$C$100000) -> 19212800 | E38: =SUMIF(Tienda_4!$G$2:$G$100000,$A38,Tienda_4!$C$2:$C$100000) -> 17108300 | F38: =SUM(B38:E38) -> 67149900 | G38: =IFERROR(F38/$F$49,0) -> 0.015248798 | H38: =COUNTIF(Tienda_1!$G$2:$G$100000,$A38)+COUNTIF(Tienda_2!$G$2:$G$100000,$A38)+COUNTIF(Tienda_3!$G$2:$G$100000,$A38)+COUNTIF(Tienda_4!$G$2:$G$100000,$A38) -> 142
A39: Manizales | B39: =SUMIF(Tienda_1!$G$2:$G$100000,$A39,Tienda_1!$C$2:$C$100000) -> 8027600 | C39: =SUMIF(Tienda_2!$G$2:$G$100000,$A39,Tienda_2!$C$2:$C$100000) -> 3539900 | D39: =SUMIF(Tienda_3!$G$2:$G$100000,$A39,Tienda_3!$C$2:$C$100000) -> 6501800 | E39: =SUMIF(Tienda_4!$G$2:$G$100000,$A39,Tienda_4!$C$2:$C$100000) -> 1298600 | F39: =SUM(B39:E39) -> 19367900 | G39: =IFERROR(F39/$F$49,0) -> 0.0043981778 | H39: =COUNTIF(Tienda_1!$G$2:$G$100000,$A39)+COUNTIF(Tienda_2!$G$2:$G$100000,$A39)+COUNTIF(Tienda_3!$G$2:$G$100000,$A39)+COUNTIF(Tienda_4!$G$2:$G$100000,$A39) -> 41
A40: Medellín | B40: =SUMIF(Tienda_1!$G$2:$G$100000,$A40,Tienda_1!$C$2:$C$100000) -> 296858100 | C40: =SUMIF(Tienda_2!$G$2:$G$100000,$A40,Tienda_2!$C$2:$C$100000) -> 297246700 | D40: =SUMIF(Tienda_3!$G$2:$G$100000,$A40,Tienda_3!$C$2:$C$100000) -> 250580600 | E40: =SUMIF(Tienda_4!$G$2:$G$100000,$A40,Tienda_4!$C$2:$C$100000) -> 251983800 | F40: =SUM(B40:E40) -> 1096669200 | G40: =IFERROR(F40/$F$49,0) -> 0.24903815 | H40: =COUNTIF(Tienda_1!$G$2:$G$100000,$A40)+COUNTIF(Tienda_2!$G$2:$G$100000,$A40)+COUNTIF(Tienda_3!$G$2:$G$100000,$A40)+COUNTIF(Tienda_4!$G$2:$G$100000,$A40) -> 2314
A41: Neiva | B41: =SUMIF(Tienda_1!$G$2:$G$100000,$A41,Tienda_1!$C$2:$C$100000) -> 3494000 | C41: =SUMIF(Tienda_2!$G$2:$G$100000,$A41,Tienda_2!$C$2:$C$100000) -> 3839400 | D41: =SUMIF(Tienda_3!$G$2:$G$100000,$A41,Tienda_3!$C$2:$C$100000) -> 4359500 | E41: =SUMIF(Tienda_4!$G$2:$G$100000,$A41,Tienda_4!$C$2:$C$100000) -> 9205100 | F41: =SUM(B41:E41) -> 20898000 | G41: =IFERROR(F41/$F$49,0) -> 0.0047456419 | H41: =COUNTIF(Tienda_1!$G$2:$G$100000,$A41)+COUNTIF(Tienda_2!$G$2:$G$100000,$A41)+COUNTIF(Tienda_3!$G$2:$G$100000,$A41)+COUNTIF(Tienda_4!$G$2:$G$100000,$A41) -> 40
... A48: Villavicencio | B48: =SUMIF(Tienda_1!$G$2:$G$100000,$A48,Tienda_1!$C$2:$C$100000) -> 7161900 | C48: =SUMIF(Tienda_2!$G$2:$G$100000,$A48,Tienda_2!$C$2:$C$100000) -> 3597100 | D48: =SUMIF(Tienda_3!$G$2:$G$100000,$A48,Tienda_3!$C$2:$C$100000) -> 988000 | E48: =SUMIF(Tienda_4!$G$2:$G$100000,$A48,Tienda_4!$C$2:$C$100000) -> 1586600 | F48: =SUM(B48:E48) -> 13333600 | G48: =IFERROR(F48/$F$49,0) -> 0.0030278731 | H48: =COUNTIF(Tienda_1!$G$2:$G$100000,$A48)+COUNTIF(Tienda_2!$G$2:$G$100000,$A48)+COUNTIF(Tienda_3!$G$2:$G$100000,$A48)+COUNTIF(Tienda_4!$G$2:$G$100000,$A48) -> 29
...

Sheet Resumen
B2: Resumen ejecutivo — Ventas Tiendas 1 a 4
B3: Vinculado a la hoja Análisis: se actualiza automáticamente al editar los datos de las tiendas.
B5: Indicadores globales
B6: Ingresos totales | C6: =Análisis!$F$7 -> 4403619200
B7: N° total de ventas | C7: =Análisis!$F$6 -> 9435
B8: Ticket promedio | C8: =Análisis!$F$8 -> 466732.29
B9: Costo de envío total | C9: =Análisis!$F$9 -> 234697000
B10: Ingreso neto de envíos | C10: =Análisis!$F$11 -> 4168922200
B11: Calificación promedio (1-5) | C11: =Análisis!$F$12 -> 4.0145204
B12: Cuotas promedio | C12: =Análisis!$F$13 -> 2.927398
B13: Envío como % de ingresos | C13: =IFERROR(Análisis!$F$9/Análisis!$F$7,0) -> 0.053296389
B15: Comparativo por tienda
B16: Tienda | C16: Ingresos | D16: % del total | E16: Ticket promedio | F16: Calificación
B17: =Análisis!B5 -> Tienda 1 | C17: =Análisis!B7 -> 1150880400 | D17: =Análisis!B14 -> 0.26134876 | E17: =Análisis!B8 -> 487867.91 | F17: =Análisis!B12 -> 3.976685
B18: =Análisis!C5 -> Tienda 2 | C18: =Análisis!C7 -> 1116343500 | D18: =Análisis!C14 -> 0.25350591 | E18: =Análisis!C8 -> 473227.43 | F18: =Análisis!C12 -> 4.0373039
B19: =Análisis!D5 -> Tienda 3 | C19: =Análisis!D7 -> 1098019600 | D19: =Análisis!D14 -> 0.24934481 | E19: =Análisis!D8 -> 465459.77 | F19: =Análisis!D12 -> 4.0483256
B20: =Análisis!E5 -> Tienda 4 | C20: =Análisis!E7 -> 1038375700 | D20: =Análisis!E14 -> 0.23580052 | E20: =Análisis!E8 -> 440362.89 | F20: =Análisis!E12 -> 3.9957591
B21: Total | C21: =SUM(C17:C20) -> 4403619200 | D21: =SUM(D17:D20) -> 1 | E21: =Análisis!F8 -> 466732.29 | F21: =Análisis!F12 -> 4.0145204
B23: Rankings (Top 3 y último)
B24: Dimensión / Puesto | C24: Nombre | D24: Ingresos
B25: Categorías
B26: 1° | C26: =INDEX(Análisis!$A$18:$A$25,MATCH(LARGE(Análisis!$F$18:$F$25,1),Análisis!$F$18:$F$25,0)) -> Electrónicos | D26: =LARGE(Análisis!$F$18:$F$25,1) -> 1660576500
B27: 2° | C27: =INDEX(Análisis!$A$18:$A$25,MATCH(LARGE(Análisis!$F$18:$F$25,2),Análisis!$F$18:$F$25,0)) -> Electrodomésticos | D27: =LARGE(Análisis!$F$18:$F$25,2) -> 1324751100
B28: 3° | C28: =INDEX(Análisis!$A$18:$A$25,MATCH(LARGE(Análisis!$F$18:$F$25,3),Análisis!$F$18:$F$25,0)) -> Muebles | D28: =LARGE(Análisis!$F$18:$F$25,3) -> 757661000
B29: Último | C29: =INDEX(Análisis!$A$18:$A$25,MATCH(MIN(Análisis!$F$18:$F$25),Análisis!$F$18:$F$25,0)) -> Libros | D29: =MIN(Análisis!$F$18:$F$25) -> 37696100
B31: Ciudades
B32: 1° | C32: =INDEX(Análisis!$A$30:$A$48,MATCH(LARGE(Análisis!$F$30:$F$48,1),Análisis!$F$30:$F$48,0)) -> Bogotá | D32: =LARGE(Análisis!$F$30:$F$48,1) -> 1814858300
B33: 2° | C33: =INDEX(Análisis!$A$30:$A$48,MATCH(LARGE(Análisis!$F$30:$F$48,2),Análisis!$F$30:$F$48,0)) -> Medellín | D33: =LARGE(Análisis!$F$30:$F$48,2) -> 1096669200
B34: 3° | C34: =INDEX(Análisis!$A$30:$A$48,MATCH(LARGE(Análisis!$F$30:$F$48,3),Análisis!$F$30:$F$48,0)) -> Cali | D34: =LARGE(Análisis!$F$30:$F$48,3) -> 506526100
B35: Último | C35: =INDEX(Análisis!$A$30:$A$48,MATCH(MIN(Análisis!$F$30:$F$48),Análisis!$F$30:$F$48,0)) -> Valledupar | D35: =MIN(Análisis!$F$30:$F$48) -> 5886300
B37: Vendedores
B38: 1° | C38: =INDEX(Análisis!$A$53:$A$66,MATCH(LARGE(Análisis!$C$53:$C$66,1),Análisis!$C$53:$C$66,0)) -> Felipe Santos | D38: =LARGE(Análisis!$C$53:$C$66,1) -> 353796000
B39: 2° | C39: =INDEX(Análisis!$A$53:$A$66,MATCH(LARGE(Análisis!$C$53:$C$66,2),Análisis!$C$53:$C$66,0)) -> Izabela de León | D39: =LARGE(Análisis!$C$53:$C$66,2) -> 350342400
B40: 3° | C40: =INDEX(Análisis!$A$53:$A$66,MATCH(LARGE(Análisis!$C$53:$C$66,3),Análisis!$C$53:$C$66,0)) -> Maria Alfonso | D40: =LARGE(Análisis!$C$53:$C$66,3) -> 349694800
B41: Último | C41: =INDEX(Análisis!$A$53:$A$66,MATCH(MIN(Análisis!$C$53:$C$66),Análisis!$C$53:$C$66,0)) -> Mariana Herrera | D41: =MIN(Análisis!$C$53:$C$66) -> 283302600
B43: Tendencia anual
B44: Año | C44: Ingresos | D44: % del total | E44: Variación vs año anterior
B45: =Análisis!A71 -> 2020 | C45: =Análisis!F71 -> 1341955000 | D45: =Análisis!G71 -> 0.30473911 | E45: =""
B46: =Análisis!A72 -> 2021 | C46: =Análisis!F72 -> 1424114300 | D46: =Análisis!G72 -> 0.32339633 | E46: =IFERROR(C46/C45-1,"") -> 0.061223588
B47: =Análisis!A73 -> 2022 | C47: =Análisis!F73 -> 1327451900 | D47: =Análisis!G73 -> 0.30144566 | E47: =IFERROR(C47/C46-1,"") -> -0.067875451
...

Sheet Dashboard
AB1: Datos de apoyo del Dashboard (vinculados a Análisis)
B2: DASHBOARD DE VENTAS — TIENDAS 1 A 4
B3: Todos los indicadores se recalculan automáticamente al editar las hojas Tienda_1 a Tienda_4 | AB3: Tienda | AC3: Ingresos | AD3: Calificación | AE3: Ticket promedio
AB4: =Análisis!B5 -> Tienda 1 | AC4: =Análisis!B7 -> 1150880400 | AD4: =Análisis!B12 -> 3.976685 | AE4: =Análisis!B8 -> 487867.91
B5: INGRESOS TOTALES | F5: N° DE VENTAS | J5: CALIFICACIÓN PROMEDIO | N5: COSTO DE ENVÍO | AB5: =Análisis!C5 -> Tienda 2 | AC5: =Análisis!C7 -> 1116343500 | AD5: =Análisis!C12 -> 4.0373039 | AE5: =Análisis!C8 -> 473227.43
B6: =Análisis!$F$7 -> 4403619200 | F6: =Análisis!$F$6 -> 9435 | J6: =Análisis!$F$12 -> 4.0145204 | N6: =Análisis!$F$9 -> 234697000 | AB6: =Análisis!D5 -> Tienda 3 | AC6: =Análisis!D7 -> 1098019600 | AD6: =Análisis!D12 -> 4.0483256 | AE6: =Análisis!D8 -> 465459.77
B7: ="Ingreso neto de envíos: "&TEXT(Análisis!$F$11,"$#.##0") -> Ingreso neto de envíos: $4.168.922.200 | F7: ="Ticket promedio: "&TEXT(Análisis!$F$8,"$#.##0") -> Ticket promedio: $466.732 | J7: ="Mejor: "&Análisis!$B$88&" ("&TEXT(Análisis!$C$88,"0,00")&")" -> Mejor: Tienda 3 (4,05) | N7: ="Equivale al "&TEXT(Análisis!$F$9/Análisis!$F$7,"0,0%")&" de los ingresos" -> Equivale al 5,3% de los ingresos | AB7: =Análisis!E5 -> Tienda 4 | AC7: =Análisis!E7 -> 1038375700 | AD7: =Análisis!E12 -> 3.9957591 | AE7: =Análisis!E8 -> 440362.89
B9: TIENDA LÍDER | F9: CATEGORÍA LÍDER | J9: CIUDAD LÍDER | N9: VENDEDOR LÍDER | AB9: Categoría | AC9: Ingresos
B10: =Análisis!$B$86 -> Tienda 1 | F10: =Análisis!$B$90 -> Electrónicos | J10: =Análisis!$B$92 -> Bogotá | N10: =Análisis!$B$93 -> Felipe Santos | AB10: =INDEX(Análisis!$A$18:$A$25,MATCH(LARGE(Análisis!$F$18:$F$25,1),Análisis!$F$18:$F$25,0)) -> Electrónicos | AC10: =LARGE(Análisis!$F$18:$F$25,1) -> 1660576500
B11: ="Ingresos: "&TEXT(Análisis!$C$86,"$#.##0") -> Ingresos: $1.150.880.400 | F11: ="Ingresos: "&TEXT(Análisis!$C$90,"$#.##0") -> Ingresos: $1.660.576.500 | J11: ="Ingresos: "&TEXT(Análisis!$C$92,"$#.##0") -> Ingresos: $1.814.858.300 | N11: ="Ingresos: "&TEXT(Análisis!$C$93,"$#.##0") -> Ingresos: $353.796.000 | AB11: =INDEX(Análisis!$A$18:$A$25,MATCH(LARGE(Análisis!$F$18:$F$25,2),Análisis!$F$18:$F$25,0)) -> Electrodomésticos | AC11: =LARGE(Análisis!$F$18:$F$25,2) -> 1324751100
AB12: =INDEX(Análisis!$A$18:$A$25,MATCH(LARGE(Análisis!$F$18:$F$25,3),Análisis!$F$18:$F$25,0)) -> Muebles | AC12: =LARGE(Análisis!$F$18:$F$25,3) -> 757661000
AB13: =INDEX(Análisis!$A$18:$A$25,MATCH(LARGE(Análisis!$F$18:$F$25,4),Análisis!$F$18:$F$25,0)) -> Instrumentos musicales | AC13: =LARGE(Análisis!$F$18:$F$25,4) -> 348772600
AB14: =INDEX(Análisis!$A$18:$A$25,MATCH(LARGE(Análisis!$F$18:$F$25,5),Análisis!$F$18:$F$25,0)) -> Deportes y diversión | AC14: =LARGE(Análisis!$F$18:$F$25,5) -> 142977700
AB15: =INDEX(Análisis!$A$18:$A$25,MATCH(LARGE(Análisis!$F$18:$F$25,6),Análisis!$F$18:$F$25,0)) -> Juguetes | AC15: =LARGE(Análisis!$F$18:$F$25,6) -> 73604400
AB16: =INDEX(Análisis!$A$18:$A$25,MATCH(LARGE(Análisis!$F$18:$F$25,7),Análisis!$F$18:$F$25,0)) -> Artículos para el hogar | AC16: =LARGE(Análisis!$F$18:$F$25,7) -> 57579800
AB17: =INDEX(Análisis!$A$18:$A$25,MATCH(LARGE(Análisis!$F$18:$F$25,8),Análisis!$F$18:$F$25,0)) -> Libros | AC17: =LARGE(Análisis!$F$18:$F$25,8) -> 37696100
AB19: Ciudad | AC19: Ingresos
AB20: =INDEX(Análisis!$A$30:$A$48,MATCH(LARGE(Análisis!$F$30:$F$48,1),Análisis!$F$30:$F$48,0)) -> Bogotá | AC20: =LARGE(Análisis!$F$30:$F$48,1) -> 1814858300
AB21: =INDEX(Análisis!$A$30:$A$48,MATCH(LARGE(Análisis!$F$30:$F$48,2),Análisis!$F$30:$F$48,0)) -> Medellín | AC21: =LARGE(Análisis!$F$30:$F$48,2) -> 1096669200
AB22: =INDEX(Análisis!$A$30:$A$48,MATCH(LARGE(Análisis!$F$30:$F$48,3),Análisis!$F$30:$F$48,0)) -> Cali | AC22: =LARGE(Análisis!$F$30:$F$48,3) -> 506526100
AB23: =INDEX(Análisis!$A$30:$A$48,MATCH(LARGE(Análisis!$F$30:$F$48,4),Análisis!$F$30:$F$48,0)) -> Pereira | AC23: =LARGE(Análisis!$F$30:$F$48,4) -> 225927300
AB24: =INDEX(Análisis!$A$30:$A$48,MATCH(LARGE(Análisis!$F$30:$F$48,5),Análisis!$F$30:$F$48,0)) -> Barranquilla | AC24: =LARGE(Análisis!$F$30:$F$48,5) -> 132040500
AB25: =INDEX(Análisis!$A$30:$A$48,MATCH(LARGE(Análisis!$F$30:$F$48,6),Análisis!$F$30:$F$48,0)) -> Cartagena | AC25: =LARGE(Análisis!$F$30:$F$48,6) -> 102376700
AB26: =INDEX(Análisis!$A$30:$A$48,MATCH(LARGE(Análisis!$F$30:$F$48,7),Análisis!$F$30:$F$48,0)) -> Cúcuta | AC26: =LARGE(Análisis!$F$30:$F$48,7) -> 99369100
AB27: =INDEX(Análisis!$A$30:$A$48,MATCH(LARGE(Análisis!$F$30:$F$48,8),Análisis!$F$30:$F$48,0)) -> Bucaramanga | AC27: =LARGE(Análisis!$F$30:$F$48,8) -> 90573300
AB28: =INDEX(Análisis!$A$30:$A$48,MATCH(LARGE(Análisis!$F$30:$F$48,9),Análisis!$F$30:$F$48,0)) -> Riohacha | AC28: =LARGE(Análisis!$F$30:$F$48,9) -> 73879700
AB29: =INDEX(Análisis!$A$30:$A$48,MATCH(LARGE(Análisis!$F$30:$F$48,10),Análisis!$F$30:$F$48,0)) -> Leticia | AC29: =LARGE(Análisis!$F$30:$F$48,10) -> 67149900
AB31: Año | AC31: Ingresos
AB32: =TEXT(Análisis!A71,"0") -> 2020 | AC32: =Análisis!F71 -> 1341955000
AB33: =TEXT(Análisis!A72,"0") -> 2021 | AC33: =Análisis!F72 -> 1424114300
AB34: =TEXT(Análisis!A73,"0") -> 2022 | AC34: =Análisis!F73 -> 1327451900
AB35: =TEXT(Análisis!A74,"0") -> 2023 | AC35: =Análisis!F74 -> 310098000
AB37: Método de pago | AC37: Ingresos
AB38: =Análisis!A79 -> Cupón | AC38: =Análisis!F79 -> 235869600
AB39: =Análisis!A80 -> Nequi | AC39: =Análisis!F80 -> 880684200
AB40: =Análisis!A81 -> Tarjeta de crédito | AC40: =Análisis!F81 -> 3230607100
AB41: =Análisis!A82 -> Tarjeta de débito | AC41: =Análisis!F82 -> 56458300
AB43: Vendedor | AC43: Ingresos
AB44: =INDEX(Análisis!$A$53:$A$66,MATCH(LARGE(Análisis!$C$53:$C$66,1),Análisis!$C$53:$C$66,0)) -> Felipe Santos | AC44: =LARGE(Análisis!$C$53:$C$66,1) -> 353796000
AB45: =INDEX(Análisis!$A$53:$A$66,MATCH(LARGE(Análisis!$C$53:$C$66,2),Análisis!$C$53:$C$66,0)) -> Izabela de León | AC45: =LARGE(Análisis!$C$53:$C$66,2) -> 350342400
...

Sheet Datos_Consolidados
A1: Tienda | B1: Categoría | C1: Ciudad | D1: Vendedor | E1: Método de pago | F1: Año | G1: Precio | H1: Costo envío | I1: Calificación | J1: Incluir | N1: Listas y datos de apoyo (vinculados)
A2: =IF(Tienda_1!$A2="","","Tienda 1") -> Tienda 1 | B2: =IF($A2="","",Tienda_1!B2) -> Electrónicos | C2: =IF($A2="","",Tienda_1!G2) -> Bogotá | D2: =IF($A2="","",Tienda_1!F2) -> Pedro Gomez | E2: =IF($A2="","",Tienda_1!I2) -> Tarjeta de crédito | F2: =IF($A2="","",VALUE(RIGHT(Tienda_1!E2,4))) -> 2021 | G2: =IF($A2="","",Tienda_1!C2) -> 164300 | H2: =IF($A2="","",Tienda_1!D2) -> 6900 | I2: =IF($A2="","",Tienda_1!H2) -> 4 | J2: =IF($A2="",0,IF(AND(OR('Cuadro-de-mando'!$B$4="(Todas)",'Cuadro-de-mando'!$B$4=$A2),OR('Cuadro-de-mando'!$E$4="(Todas)",'Cuadro-de-mando'!$E$4=$B2),OR('Cuadro-de-mando'!$H$4="(Todas)",'Cuadro-de-mando'!$H$4=$C2),OR('Cuadro-de-mando'!$K$4="(Todas)",'Cuadro-de-mando'!$K$4=$E2),OR('Cuadro-de-mando'!$N$4="(Todos)",'Cuadro-de-mando'!$N$4=$F2)),1,0)) -> 1 | N2: Tiendas | O2: Categorías | P2: Ciudades | Q2: Métodos de pago | R2: Años | T2: Tienda | U2: Ingresos (filtrado) | W2: Categoría | X2: Ingresos | Y2: Desempate | Z2: Top categorías | AA2: Ingresos
A3: =IF(Tienda_1!$A3="","","Tienda 1") -> Tienda 1 | B3: =IF($A3="","",Tienda_1!B3) -> Muebles | C3: =IF($A3="","",Tienda_1!G3) -> Medellín | D3: =IF($A3="","",Tienda_1!F3) -> Beatriz Morales | E3: =IF($A3="","",Tienda_1!I3) -> Tarjeta de crédito | F3: =IF($A3="","",VALUE(RIGHT(Tienda_1!E3,4))) -> 2022 | G3: =IF($A3="","",Tienda_1!C3) -> 192300 | H3: =IF($A3="","",Tienda_1!D3) -> 8400 | I3: =IF($A3="","",Tienda_1!H3) -> 1 | J3: =IF($A3="",0,IF(AND(OR('Cuadro-de-mando'!$B$4="(Todas)",'Cuadro-de-mando'!$B$4=$A3),OR('Cuadro-de-mando'!$E$4="(Todas)",'Cuadro-de-mando'!$E$4=$B3),OR('Cuadro-de-mando'!$H$4="(Todas)",'Cuadro-de-mando'!$H$4=$C3),OR('Cuadro-de-mando'!$K$4="(Todas)",'Cuadro-de-mando'!$K$4=$E3),OR('Cuadro-de-mando'!$N$4="(Todos)",'Cuadro-de-mando'!$N$4=$F3)),1,0)) -> 1 | N3: (Todas) | O3: (Todas) | P3: (Todas) | Q3: (Todas) | R3: (Todos) | T3: =N4 -> Tienda 1 | U3: =SUMIFS(Datos_Consolidados!$G$2:$G$9601,Datos_Consolidados!$J$2:$J$9601,1,Datos_Consolidados!$A$2:$A$9601,$T3) -> 1150880400 | W3: =O4 -> Artículos para el hogar | X3: =SUMIFS(Datos_Consolidados!$G$2:$G$9601,Datos_Consolidados!$J$2:$J$9601,1,Datos_Consolidados!$B$2:$B$9601,$W3) -> 57579800 | Y3: =X3-ROW()*0.000001 -> 57579800 | Z3: =IFERROR(INDEX($W$3:$W$10,MATCH(LARGE($Y$3:$Y$10,1),$Y$3:$Y$10,0)),"") -> Electrónicos | AA3: =IFERROR(INDEX($X$3:$X$10,MATCH(LARGE($Y$3:$Y$10,1),$Y$3:$Y$10,0)),0) -> 1660576500
A4: =IF(Tienda_1!$A4="","","Tienda 1") -> Tienda 1 | B4: =IF($A4="","",Tienda_1!B4) -> Juguetes | C4: =IF($A4="","",Tienda_1!G4) -> Cartagena | D4: =IF($A4="","",Tienda_1!F4) -> Juan Fernandez | E4: =IF($A4="","",Tienda_1!I4) -> Tarjeta de crédito | F4: =IF($A4="","",VALUE(RIGHT(Tienda_1!E4,4))) -> 2021 | G4: =IF($A4="","",Tienda_1!C4) -> 209600 | H4: =IF($A4="","",Tienda_1!D4) -> 15900 | I4: =IF($A4="","",Tienda_1!H4) -> 1 | J4: =IF($A4="",0,IF(AND(OR('Cuadro-de-mando'!$B$4="(Todas)",'Cuadro-de-mando'!$B$4=$A4),OR('Cuadro-de-mando'!$E$4="(Todas)",'Cuadro-de-mando'!$E$4=$B4),OR('Cuadro-de-mando'!$H$4="(Todas)",'Cuadro-de-mando'!$H$4=$C4),OR('Cuadro-de-mando'!$K$4="(Todas)",'Cuadro-de-mando'!$K$4=$E4),OR('Cuadro-de-mando'!$N$4="(Todos)",'Cuadro-de-mando'!$N$4=$F4)),1,0)) -> 1 | N4: =Análisis!B5 -> Tienda 1 | O4: =Análisis!A18 -> Artículos para el hogar | P4: =Análisis!A30 -> Armenia | Q4: =Análisis!A79 -> Cupón | R4: =Análisis!A71 -> 2020 | T4: =N5 -> Tienda 2 | U4: =SUMIFS(Datos_Consolidados!$G$2:$G$9601,Datos_Consolidados!$J$2:$J$9601,1,Datos_Consolidados!$A$2:$A$9601,$T4) -> 1116343500 | W4: =O5 -> Deportes y diversión | X4: =SUMIFS(Datos_Consolidados!$G$2:$G$9601,Datos_Consolidados!$J$2:$J$9601,1,Datos_Consolidados!$B$2:$B$9601,$W4) -> 142977700 | Y4: =X4-ROW()*0.000001 -> 1.429777e+08 | Z4: =IFERROR(INDEX($W$3:$W$10,MATCH(LARGE($Y$3:$Y$10,2),$Y$3:$Y$10,0)),"") -> Electrodomésticos | AA4: =IFERROR(INDEX($X$3:$X$10,MATCH(LARGE($Y$3:$Y$10,2),$Y$3:$Y$10,0)),0) -> 1324751100
A5: =IF(Tienda_1!$A5="","","Tienda 1") -> Tienda 1 | B5: =IF($A5="","",Tienda_1!B5) -> Electrodomésticos | C5: =IF($A5="","",Tienda_1!G5) -> Cali | D5: =IF($A5="","",Tienda_1!F5) -> Juan Fernandez | E5: =IF($A5="","",Tienda_1!I5) -> Nequi | F5: =IF($A5="","",VALUE(RIGHT(Tienda_1!E5,4))) -> 2022 | G5: =IF($A5="","",Tienda_1!C5) -> 757500 | H5: =IF($A5="","",Tienda_1!D5) -> 41000 | I5: =IF($A5="","",Tienda_1!H5) -> 4 | J5: =IF($A5="",0,IF(AND(OR('Cuadro-de-mando'!$B$4="(Todas)",'Cuadro-de-mando'!$B$4=$A5),OR('Cuadro-de-mando'!$E$4="(Todas)",'Cuadro-de-mando'!$E$4=$B5),OR('Cuadro-de-mando'!$H$4="(Todas)",'Cuadro-de-mando'!$H$4=$C5),OR('Cuadro-de-mando'!$K$4="(Todas)",'Cuadro-de-mando'!$K$4=$E5),OR('Cuadro-de-mando'!$N$4="(Todos)",'Cuadro-de-mando'!$N$4=$F5)),1,0)) -> 1 | N5: =Análisis!C5 -> Tienda 2 | O5: =Análisis!A19 -> Deportes y diversión | P5: =Análisis!A31 -> Barranquilla | Q5: =Análisis!A80 -> Nequi | R5: =Análisis!A72 -> 2021 | T5: =N6 -> Tienda 3 | U5: =SUMIFS(Datos_Consolidados!$G$2:$G$9601,Datos_Consolidados!$J$2:$J$9601,1,Datos_Consolidados!$A$2:$A$9601,$T5) -> 1098019600 | W5: =O6 -> Electrodomésticos | X5: =SUMIFS(Datos_Consolidados!$G$2:$G$9601,Datos_Consolidados!$J$2:$J$9601,1,Datos_Consolidados!$B$2:$B$9601,$W5) -> 1324751100 | Y5: =X5-ROW()*0.000001 -> 1.3247511e+09 | Z5: =IFERROR(INDEX($W$3:$W$10,MATCH(LARGE($Y$3:$Y$10,3),$Y$3:$Y$10,0)),"") -> Muebles | AA5: =IFERROR(INDEX($X$3:$X$10,MATCH(LARGE($Y$3:$Y$10,3),$Y$3:$Y$10,0)),0) -> 757661000
A6: =IF(Tienda_1!$A6="","","Tienda 1") -> Tienda 1 | B6: =IF($A6="","",Tienda_1!B6) -> Muebles | C6: =IF($A6="","",Tienda_1!G6) -> Medellín | D6: =IF($A6="","",Tienda_1!F6) -> Maria Alfonso | E6: =IF($A6="","",Tienda_1!I6) -> Nequi | F6: =IF($A6="","",VALUE(RIGHT(Tienda_1!E6,4))) -> 2020 | G6: =IF($A6="","",Tienda_1!C6) -> 335200 | H6: =IF($A6="","",Tienda_1!D6) -> 20200 | I6: =IF($A6="","",Tienda_1!H6) -> 5 | J6: =IF($A6="",0,IF(AND(OR('Cuadro-de-mando'!$B$4="(Todas)",'Cuadro-de-mando'!$B$4=$A6),OR('Cuadro-de-mando'!$E$4="(Todas)",'Cuadro-de-mando'!$E$4=$B6),OR('Cuadro-de-mando'!$H$4="(Todas)",'Cuadro-de-mando'!$H$4=$C6),OR('Cuadro-de-mando'!$K$4="(Todas)",'Cuadro-de-mando'!$K$4=$E6),OR('Cuadro-de-mando'!$N$4="(Todos)",'Cuadro-de-mando'!$N$4=$F6)),1,0)) -> 1 | N6: =Análisis!D5 -> Tienda 3 | O6: =Análisis!A20 -> Electrodomésticos | P6: =Análisis!A32 -> Bogotá | Q6: =Análisis!A81 -> Tarjeta de crédito | R6: =Análisis!A73 -> 2022 | T6: =N7 -> Tienda 4 | U6: =SUMIFS(Datos_Consolidados!$G$2:$G$9601,Datos_Consolidados!$J$2:$J$9601,1,Datos_Consolidados!$A$2:$A$9601,$T6) -> 1038375700 | W6: =O7 -> Electrónicos | X6: =SUMIFS(Datos_Consolidados!$G$2:$G$9601,Datos_Consolidados!$J$2:$J$9601,1,Datos_Consolidados!$B$2:$B$9601,$W6) -> 1660576500 | Y6: =X6-ROW()*0.000001 -> 1.6605765e+09 | Z6: =IFERROR(INDEX($W$3:$W$10,MATCH(LARGE($Y$3:$Y$10,4),$Y$3:$Y$10,0)),"") -> Instrumentos musicales | AA6: =IFERROR(INDEX($X$3:$X$10,MATCH(LARGE($Y$3:$Y$10,4),$Y$3:$Y$10,0)),0) -> 348772600
A7: =IF(Tienda_1!$A7="","","Tienda 1") -> Tienda 1 | B7: =IF($A7="","",Tienda_1!B7) -> Juguetes | C7: =IF($A7="","",Tienda_1!G7) -> Cali | D7: =IF($A7="","",Tienda_1!F7) -> Beatriz Morales | E7: =IF($A7="","",Tienda_1!I7) -> Cupón | F7: =IF($A7="","",VALUE(RIGHT(Tienda_1!E7,4))) -> 2020 | G7: =IF($A7="","",Tienda_1!C7) -> 24200 | H7: =IF($A7="","",Tienda_1!D7) -> 0 | I7: =IF($A7="","",Tienda_1!H7) -> 5 | J7: =IF($A7="",0,IF(AND(OR('Cuadro-de-mando'!$B$4="(Todas)",'Cuadro-de-mando'!$B$4=$A7),OR('Cuadro-de-mando'!$E$4="(Todas)",'Cuadro-de-mando'!$E$4=$B7),OR('Cuadro-de-mando'!$H$4="(Todas)",'Cuadro-de-mando'!$H$4=$C7),OR('Cuadro-de-mando'!$K$4="(Todas)",'Cuadro-de-mando'!$K$4=$E7),OR('Cuadro-de-mando'!$N$4="(Todos)",'Cuadro-de-mando'!$N$4=$F7)),1,0)) -> 1 | N7: =Análisis!E5 -> Tienda 4 | O7: =Análisis!A21 -> Electrónicos | P7: =Análisis!A33 -> Bucaramanga | Q7: =Análisis!A82 -> Tarjeta de débito | R7: =Análisis!A74 -> 2023 | W7: =O8 -> Instrumentos musicales | X7: =SUMIFS(Datos_Consolidados!$G$2:$G$9601,Datos_Consolidados!$J$2:$J$9601,1,Datos_Consolidados!$B$2:$B$9601,$W7) -> 348772600 | Y7: =X7-ROW()*0.000001 -> 3.487726e+08 | Z7: =IFERROR(INDEX($W$3:$W$10,MATCH(LARGE($Y$3:$Y$10,5),$Y$3:$Y$10,0)),"") -> Deportes y diversión | AA7: =IFERROR(INDEX($X$3:$X$10,MATCH(LARGE($Y$3:$Y$10,5),$Y$3:$Y$10,0)),0) -> 142977700
A8: =IF(Tienda_1!$A8="","","Tienda 1") -> Tienda 1 | B8: =IF($A8="","",Tienda_1!B8) -> Juguetes | C8: =IF($A8="","",Tienda_1!G8) -> Bogotá | D8: =IF($A8="","",Tienda_1!F8) -> Juan Fernandez | E8: =IF($A8="","",Tienda_1!I8) -> Nequi | F8: =IF($A8="","",VALUE(RIGHT(Tienda_1!E8,4))) -> 2021 | G8: =IF($A8="","",Tienda_1!C8) -> 44200 | H8: =IF($A8="","",Tienda_1!D8) -> 0 | I8: =IF($A8="","",Tienda_1!H8) -> 3 | J8: =IF($A8="",0,IF(AND(OR('Cuadro-de-mando'!$B$4="(Todas)",'Cuadro-de-mando'!$B$4=$A8),OR('Cuadro-de-mando'!$E$4="(Todas)",'Cuadro-de-mando'!$E$4=$B8),OR('Cuadro-de-mando'!$H$4="(Todas)",'Cuadro-de-mando'!$H$4=$C8),OR('Cuadro-de-mando'!$K$4="(Todas)",'Cuadro-de-mando'!$K$4=$E8),OR('Cuadro-de-mando'!$N$4="(Todos)",'Cuadro-de-mando'!$N$4=$F8)),1,0)) -> 1 | O8: =Análisis!A22 -> Instrumentos musicales | P8: =Análisis!A34 -> Cali | W8: =O9 -> Juguetes | X8: =SUMIFS(Datos_Consolidados!$G$2:$G$9601,Datos_Consolidados!$J$2:$J$9601,1,Datos_Consolidados!$B$2:$B$9601,$W8) -> 73604400 | Y8: =X8-ROW()*0.000001 -> 73604400 | Z8: =IFERROR(INDEX($W$3:$W$10,MATCH(LARGE($Y$3:$Y$10,6),$Y$3:$Y$10,0)),"") -> Juguetes | AA8: =IFERROR(INDEX($X$3:$X$10,MATCH(LARGE($Y$3:$Y$10,6),$Y$3:$Y$10,0)),0) -> 73604400
A9: =IF(Tienda_1!$A9="","","Tienda 1") -> Tienda 1 | B9: =IF($A9="","",Tienda_1!B9) -> Electrodomésticos | C9: =IF($A9="","",Tienda_1!G9) -> Santa Marta | D9: =IF($A9="","",Tienda_1!F9) -> Felipe Santos | E9: =IF($A9="","",Tienda_1!I9) -> Tarjeta de crédito | F9: =IF($A9="","",VALUE(RIGHT(Tienda_1!E9,4))) -> 2021 | G9: =IF($A9="","",Tienda_1!C9) -> 1189700 | H9: =IF($A9="","",Tienda_1!D9) -> 63700 | I9: =IF($A9="","",Tienda_1!H9) -> 5 | J9: =IF($A9="",0,IF(AND(OR('Cuadro-de-mando'!$B$4="(Todas)",'Cuadro-de-mando'!$B$4=$A9),OR('Cuadro-de-mando'!$E$4="(Todas)",'Cuadro-de-mando'!$E$4=$B9),OR('Cuadro-de-mando'!$H$4="(Todas)",'Cuadro-de-mando'!$H$4=$C9),OR('Cuadro-de-mando'!$K$4="(Todas)",'Cuadro-de-mando'!$K$4=$E9),OR('Cuadro-de-mando'!$N$4="(Todos)",'Cuadro-de-mando'!$N$4=$F9)),1,0)) -> 1 | O9: =Análisis!A23 -> Juguetes | P9: =Análisis!A35 -> Cartagena | T9: Año | U9: Ingresos | W9: =O10 -> Libros | X9: =SUMIFS(Datos_Consolidados!$G$2:$G$9601,Datos_Consolidados!$J$2:$J$9601,1,Datos_Consolidados!$B$2:$B$9601,$W9) -> 37696100 | Y9: =X9-ROW()*0.000001 -> 37696100 | Z9: =IFERROR(INDEX($W$3:$W$10,MATCH(LARGE($Y$3:$Y$10,7),$Y$3:$Y$10,0)),"") -> Artículos para el hogar | AA9: =IFERROR(INDEX($X$3:$X$10,MATCH(LARGE($Y$3:$Y$10,7),$Y$3:$Y$10,0)),0) -> 57579800
A10: =IF(Tienda_1!$A10="","","Tienda 1") -> Tienda 1 | B10: =IF($A10="","",Tienda_1!B10) -> Electrodomésticos | C10: =IF($A10="","",Tienda_1!G10) -> Bogotá | D10: =IF($A10="","",Tienda_1!F10) -> Izabela de León | E10: =IF($A10="","",Tienda_1!I10) -> Tarjeta de crédito | F10: =IF($A10="","",VALUE(RIGHT(Tienda_1!E10,4))) -> 2022 | G10: =IF($A10="","",Tienda_1!C10) -> 1518200 | H10: =IF($A10="","",Tienda_1!D10) -> 79000 | I10: =IF($A10="","",Tienda_1!H10) -> 1 | J10: =IF($A10="",0,IF(AND(OR('Cuadro-de-mando'!$B$4="(Todas)",'Cuadro-de-mando'!$B$4=$A10),OR('Cuadro-de-mando'!$E$4="(Todas)",'Cuadro-de-mando'!$E$4=$B10),OR('Cuadro-de-mando'!$H$4="(Todas)",'Cuadro-de-mando'!$H$4=$C10),OR('Cuadro-de-mando'!$K$4="(Todas)",'Cuadro-de-mando'!$K$4=$E10),OR('Cuadro-de-mando'!$N$4="(Todos)",'Cuadro-de-mando'!$N$4=$F10)),1,0)) -> 1 | O10: =Análisis!A24 -> Libros | P10: =Análisis!A36 -> Cúcuta | T10: =TEXT(R4,"0") -> 2020 | U10: =SUMIFS(Datos_Consolidados!$G$2:$G$9601,Datos_Consolidados!$J$2:$J$9601,1,Datos_Consolidados!$F$2:$F$9601,R4) -> 1341955000 | W10: =O11 -> Muebles | X10: =SUMIFS(Datos_Consolidados!$G$2:$G$9601,Datos_Consolidados!$J$2:$J$9601,1,Datos_Consolidados!$B$2:$B$9601,$W10) -> 757661000 | Y10: =X10-ROW()*0.000001 -> 7.57661e+08 | Z10: =IFERROR(INDEX($W$3:$W$10,MATCH(LARGE($Y$3:$Y$10,8),$Y$3:$Y$10,0)),"") -> Libros | AA10: =IFERROR(INDEX($X$3:$X$10,MATCH(LARGE($Y$3:$Y$10,8),$Y$3:$Y$10,0)),0) -> 37696100
A11: =IF(Tienda_1!$A11="","","Tienda 1") -> Tienda 1 | B11: =IF($A11="","",Tienda_1!B11) -> Juguetes | C11: =IF($A11="","",Tienda_1!G11) -> Bogotá | D11: =IF($A11="","",Tienda_1!F11) -> Beatriz Morales | E11: =IF($A11="","",Tienda_1!I11) -> Nequi | F11: =IF($A11="","",VALUE(RIGHT(Tienda_1!E11,4))) -> 2020 | G11: =IF($A11="","",Tienda_1!C11) -> 75200 | H11: =IF($A11="","",Tienda_1!D11) -> 5100 | I11: =IF($A11="","",Tienda_1!H11) -> 5 | J11: =IF($A11="",0,IF(AND(OR('Cuadro-de-mando'!$B$4="(Todas)",'Cuadro-de-mando'!$B$4=$A11),OR('Cuadro-de-mando'!$E$4="(Todas)",'Cuadro-de-mando'!$E$4=$B11),OR('Cuadro-de-mando'!$H$4="(Todas)",'Cuadro-de-mando'!$H$4=$C11),OR('Cuadro-de-mando'!$K$4="(Todas)",'Cuadro-de-mando'!$K$4=$E11),OR('Cuadro-de-mando'!$N$4="(Todos)",'Cuadro-de-mando'!$N$4=$F11)),1,0)) -> 1 | O11: =Análisis!A25 -> Muebles | P11: =Análisis!A37 -> Inírida | T11: =TEXT(R5,"0") -> 2021 | U11: =SUMIFS(Datos_Consolidados!$G$2:$G$9601,Datos_Consolidados!$J$2:$J$9601,1,Datos_Consolidados!$F$2:$F$9601,R5) -> 1424114300
A12: =IF(Tienda_1!$A12="","","Tienda 1") -> Tienda 1 | B12: =IF($A12="","",Tienda_1!B12) -> Electrodomésticos | C12: =IF($A12="","",Tienda_1!G12) -> Bogotá | D12: =IF($A12="","",Tienda_1!F12) -> Blanca Ramirez | E12: =IF($A12="","",Tienda_1!I12) -> Tarjeta de crédito | F12: =IF($A12="","",VALUE(RIGHT(Tienda_1!E12,4))) -> 2020 | G12: =IF($A12="","",Tienda_1!C12) -> 2431300 | H12: =IF($A12="","",Tienda_1!D12) -> 127600 | I12: =IF($A12="","",Tienda_1!H12) -> 5 | J12: =IF($A12="",0,IF(AND(OR('Cuadro-de-mando'!$B$4="(Todas)",'Cuadro-de-mando'!$B$4=$A12),OR('Cuadro-de-mando'!$E$4="(Todas)",'Cuadro-de-mando'!$E$4=$B12),OR('Cuadro-de-mando'!$H$4="(Todas)",'Cuadro-de-mando'!$H$4=$C12),OR('Cuadro-de-mando'!$K$4="(Todas)",'Cuadro-de-mando'!$K$4=$E12),OR('Cuadro-de-mando'!$N$4="(Todos)",'Cuadro-de-mando'!$N$4=$F12)),1,0)) -> 1 | P12: =Análisis!A38 -> Leticia | T12: =TEXT(R6,"0") -> 2022 | U12: =SUMIFS(Datos_Consolidados!$G$2:$G$9601,Datos_Consolidados!$J$2:$J$9601,1,Datos_Consolidados!$F$2:$F$9601,R6) -> 1327451900 | W12: Ciudad | X12: Ingresos | Y12: Desempate | Z12: Top 10 ciudades | AA12: Ingresos
A13: =IF(Tienda_1!$A13="","","Tienda 1") -> Tienda 1 | B13: =IF($A13="","",Tienda_1!B13) -> Electrodomésticos | C13: =IF($A13="","",Tienda_1!G13) -> Cartagena | D13: =IF($A13="","",Tienda_1!F13) -> Rafael Acosta | E13: =IF($A13="","",Tienda_1!I13) -> Tarjeta de crédito | F13: =IF($A13="","",VALUE(RIGHT(Tienda_1!E13,4))) -> 2021 | G13: =IF($A13="","",Tienda_1!C13) -> 1417100 | H13: =IF($A13="","",Tienda_1!D13) -> 75700 | I13: =IF($A13="","",Tienda_1!H13) -> 5 | J13: =IF($A13="",0,IF(AND(OR('Cuadro-de-mando'!$B$4="(Todas)",'Cuadro-de-mando'!$B$4=$A13),OR('Cuadro-de-mando'!$E$4="(Todas)",'Cuadro-de-mando'!$E$4=$B13),OR('Cuadro-de-mando'!$H$4="(Todas)",'Cuadro-de-mando'!$H$4=$C13),OR('Cuadro-de-mando'!$K$4="(Todas)",'Cuadro-de-mando'!$K$4=$E13),OR('Cuadro-de-mando'!$N$4="(Todos)",'Cuadro-de-mando'!$N$4=$F13)),1,0)) -> 1 | P13: =Análisis!A39 -> Manizales | T13: =TEXT(R7,"0") -> 2023 | U13: =SUMIFS(Datos_Consolidados!$G$2:$G$9601,Datos_Consolidados!$J$2:$J$9601,1,Datos_Consolidados!$F$2:$F$9601,R7) -> 310098000 | W13: =P4 -> Armenia | X13: =SUMIFS(Datos_Consolidados!$G$2:$G$9601,Datos_Consolidados!$J$2:$J$9601,1,Datos_Consolidados!$C$2:$C$9601,$W13) -> 12242900 | Y13: =X13-ROW()*0.000001 -> 12242900 | Z13: =IFERROR(INDEX($W$13:$W$31,MATCH(LARGE($Y$13:$Y$31,1),$Y$13:$Y$31,0)),"") -> Bogotá | AA13: =IFERROR(INDEX($X$13:$X$31,MATCH(LARGE($Y$13:$Y$31,1),$Y$13:$Y$31,0)),0) -> 1814858300
A14: =IF(Tienda_1!$A14="","","Tienda 1") -> Tienda 1 | B14: =IF($A14="","",Tienda_1!B14) -> Electrónicos | C14: =IF($A14="","",Tienda_1!G14) -> Medellín | D14: =IF($A14="","",Tienda_1!F14) -> Rafael Acosta | E14: =IF($A14="","",Tienda_1!I14) -> Tarjeta de crédito | F14: =IF($A14="","",VALUE(RIGHT(Tienda_1!E14,4))) -> 2020 | G14: =IF($A14="","",Tienda_1!C14) -> 91800 | H14: =IF($A14="","",Tienda_1!D14) -> 5300 | I14: =IF($A14="","",Tienda_1!H14) -> 1 | J14: =IF($A14="",0,IF(AND(OR('Cuadro-de-mando'!$B$4="(Todas)",'Cuadro-de-mando'!$B$4=$A14),OR('Cuadro-de-mando'!$E$4="(Todas)",'Cuadro-de-mando'!$E$4=$B14),OR('Cuadro-de-mando'!$H$4="(Todas)",'Cuadro-de-mando'!$H$4=$C14),OR('Cuadro-de-mando'!$K$4="(Todas)",'Cuadro-de-mando'!$K$4=$E14),OR('Cuadro-de-mando'!$N$4="(Todos)",'Cuadro-de-mando'!$N$4=$F14)),1,0)) -> 1 | P14: =Análisis!A40 -> Medellín | W14: =P5 -> Barranquilla | X14: =SUMIFS(Datos_Consolidados!$G$2:$G$9601,Datos_Consolidados!$J$2:$J$9601,1,Datos_Consolidados!$C$2:$C$9601,$W14) -> 132040500 | Y14: =X14-ROW()*0.000001 -> 1.320405e+08 | Z14: =IFERROR(INDEX($W$13:$W$31,MATCH(LARGE($Y$13:$Y$31,2),$Y$13:$Y$31,0)),"") -> Medellín | AA14: =IFERROR(INDEX($X$13:$X$31,MATCH(LARGE($Y$13:$Y$31,2),$Y$13:$Y$31,0)),0) -> 1096669200
A15: =IF(Tienda_1!$A15="","","Tienda 1") -> Tienda 1 | B15: =IF($A15="","",Tienda_1!B15) -> Artículos para el hogar | C15: =IF($A15="","",Tienda_1!G15) -> Pereira | D15: =IF($A15="","",Tienda_1!F15) -> Izabela de León | E15: =IF($A15="","",Tienda_1!I15) -> Tarjeta de crédito | F15: =IF($A15="","",VALUE(RIGHT(Tienda_1!E15,4))) -> 2020 | G15: =IF($A15="","",Tienda_1!C15) -> 66700 | H15: =IF($A15="","",Tienda_1!D15) -> 1700 | I15: =IF($A15="","",Tienda_1!H15) -> 4 | J15: =IF($A15="",0,IF(AND(OR('Cuadro-de-mando'!$B$4="(Todas)",'Cuadro-de-mando'!$B$4=$A15),OR('Cuadro-de-mando'!$E$4="(Todas)",'Cuadro-de-mando'!$E$4=$B15),OR('Cuadro-de-mando'!$H$4="(Todas)",'Cuadro-de-mando'!$H$4=$C15),OR('Cuadro-de-mando'!$K$4="(Todas)",'Cuadro-de-mando'!$K$4=$E15),OR('Cuadro-de-mando'!$N$4="(Todos)",'Cuadro-de-mando'!$N$4=$F15)),1,0)) -> 1 | P15: =Análisis!A41 -> Neiva | W15: =P6 -> Bogotá | X15: =SUMIFS(Datos_Consolidados!$G$2:$G$9601,Datos_Consolidados!$J$2:$J$9601,1,Datos_Consolidados!$C$2:$C$9601,$W15) -> 1814858300 | Y15: =X15-ROW()*0.000001 -> 1.8148583e+09 | Z15: =IFERROR(INDEX($W$13:$W$31,MATCH(LARGE($Y$13:$Y$31,3),$Y$13:$Y$31,0)),"") -> Cali | AA15: =IFERROR(INDEX($X$13:$X$31,MATCH(LARGE($Y$13:$Y$31,3),$Y$13:$Y$31,0)),0) -> 506526100
A16: =IF(Tienda_1!$A16="","","Tienda 1") -> Tienda 1 | B16: =IF($A16="","",Tienda_1!B16) -> Deportes y diversión | C16: =IF($A16="","",Tienda_1!G16) -> Bogotá | D16: =IF($A16="","",Tienda_1!F16) -> Juan Fernandez | E16: =IF($A16="","",Tienda_1!I16) -> Tarjeta de crédito | F16: =IF($A16="","",VALUE(RIGHT(Tienda_1!E16,4))) -> 2020 | G16: =IF($A16="","",Tienda_1!C16) -> 613300 | H16: =IF($A16="","",Tienda_1!D16) -> 30800 | I16: =IF($A16="","",Tienda_1!H16) -> 2 | J16: =IF($A16="",0,IF(AND(OR('Cuadro-de-mando'!$B$4="(Todas)",'Cuadro-de-mando'!$B$4=$A16),OR('Cuadro-de-mando'!$E$4="(Todas)",'Cuadro-de-mando'!$E$4=$B16),OR('Cuadro-de-mando'!$H$4="(Todas)",'Cuadro-de-mando'!$H$4=$C16),OR('Cuadro-de-mando'!$K$4="(Todas)",'Cuadro-de-mando'!$K$4=$E16),OR('Cuadro-de-mando'!$N$4="(Todos)",'Cuadro-de-mando'!$N$4=$F16)),1,0)) -> 1 | P16: =Análisis!A42 -> Pasto | T16: Método de pago | U16: Ingresos | W16: =P7 -> Bucaramanga | X16: =SUMIFS(Datos_Consolidados!$G$2:$G$9601,Datos_Consolidados!$J$2:$J$9601,1,Datos_Consolidados!$C$2:$C$9601,$W16) -> 90573300 | Y16: =X16-ROW()*0.000001 -> 90573300 | Z16: =IFERROR(INDEX($W$13:$W$31,MATCH(LARGE($Y$13:$Y$31,4),$Y$13:$Y$31,0)),"") -> Pereira | AA16: =IFERROR(INDEX($X$13:$X$31,MATCH(LARGE($Y$13:$Y$31,4),$Y$13:$Y$31,0)),0) -> 225927300
A17: =IF(Tienda_1!$A17="","","Tienda 1") -> Tienda 1 | B17: =IF($A17="","",Tienda_1!B17) -> Libros | C17: =IF($A17="","",Tienda_1!G17) -> Cali | D17: =IF($A17="","",Tienda_1!F17) -> Izabela de León | E17: =IF($A17="","",Tienda_1!I17) -> Tarjeta de crédito | F17: =IF($A17="","",VALUE(RIGHT(Tienda_1!E17,4))) -> 2020 | G17: =IF($A17="","",Tienda_1!C17) -> 56900 | H17: =IF($A17="","",Tienda_1!D17) -> 1200 | I17: =IF($A17="","",Tienda_1!H17) -> 5 | J17: =IF($A17="",0,IF(AND(OR('Cuadro-de-mando'!$B$4="(Todas)",'Cuadro-de-mando'!$B$4=$A17),OR('Cuadro-de-mando'!$E$4="(Todas)",'Cuadro-de-mando'!$E$4=$B17),OR('Cuadro-de-mando'!$H$4="(Todas)",'Cuadro-de-mando'!$H$4=$C17),OR('Cuadro-de-mando'!$K$4="(Todas)",'Cuadro-de-mando'!$K$4=$E17),OR('Cuadro-de-mando'!$N$4="(Todos)",'Cuadro-de-mando'!$N$4=$F17)),1,0)) -> 1 | P17: =Análisis!A43 -> Pereira | T17: =Q4 -> Cupón | U17: =SUMIFS(Datos_Consolidados!$G$2:$G$9601,Datos_Consolidados!$J$2:$J$9601,1,Datos_Consolidados!$E$2:$E$9601,$T17) -> 235869600 | W17: =P8 -> Cali | X17: =SUMIFS(Datos_Consolidados!$G$2:$G$9601,Datos_Consolidados!$J$2:$J$9601,1,Datos_Consolidados!$C$2:$C$9601,$W17) -> 506526100 | Y17: =X17-ROW()*0.000001 -> 5.065261e+08 | Z17: =IFERROR(INDEX($W$13:$W$31,MATCH(LARGE($Y$13:$Y$31,5),$Y$13:$Y$31,0)),"") -> Barranquilla | AA17: =IFERROR(INDEX($X$13:$X$31,MATCH(LARGE($Y$13:$Y$31,5),$Y$13:$Y$31,0)),0) -> 132040500
A18: =IF(Tienda_1!$A18="","","Tienda 1") -> Tienda 1 | B18: =IF($A18="","",Tienda_1!B18) -> Deportes y diversión | C18: =IF($A18="","",Tienda_1!G18) -> Medellín | D18: =IF($A18="","",Tienda_1!F18) -> Pedro Gomez | E18: =IF($A18="","",Tienda_1!I18) -> Nequi | F18: =IF($A18="","",VALUE(RIGHT(Tienda_1!E18,4))) -> 2022 | G18: =IF($A18="","",Tienda_1!C18) -> 58900 | H18: =IF($A18="","",Tienda_1!D18) -> 1300 | I18: =IF($A18="","",Tienda_1!H18) -> 2 | J18: =IF($A18="",0,IF(AND(OR('Cuadro-de-mando'!$B$4="(Todas)",'Cuadro-de-mando'!$B$4=$A18),OR('Cuadro-de-mando'!$E$4="(Todas)",'Cuadro-de-mando'!$E$4=$B18),OR('Cuadro-de-mando'!$H$4="(Todas)",'Cuadro-de-mando'!$H$4=$C18),OR('Cuadro-de-mando'!$K$4="(Todas)",'Cuadro-de-mando'!$K$4=$E18),OR('Cuadro-de-mando'!$N$4="(Todos)",'Cuadro-de-mando'!$N$4=$F18)),1,0)) -> 1 | P18: =Análisis!A44 -> Riohacha | T18: =Q5 -> Nequi | U18: =SUMIFS(Datos_Consolidados!$G$2:$G$9601,Datos_Consolidados!$J$2:$J$9601,1,Datos_Consolidados!$E$2:$E$9601,$T18) -> 880684200 | W18: =P9 -> Cartagena | X18: =SUMIFS(Datos_Consolidados!$G$2:$G$9601,Datos_Consolidados!$J$2:$J$9601,1,Datos_Consolidados!$C$2:$C$9601,$W18) -> 102376700 | Y18: =X18-ROW()*0.000001 -> 1.023767e+08 | Z18: =IFERROR(INDEX($W$13:$W$31,MATCH(LARGE($Y$13:$Y$31,6),$Y$13:$Y$31,0)),"") -> Cartagena | AA18: =IFERROR(INDEX($X$13:$X$31,MATCH(LARGE($Y$13:$Y$31,6),$Y$13:$Y$31,0)),0) -> 102376700
